Workbook

Sheet Notas
A1: CONSULTA DE NOTA - EXAMEN 1 - BIOESTADISTICA FUNDAMENTAL
A2: ➡ DIGITE AQUI SU NUMERO DE DOCUMENTO ➡ | E2: =IF($C$2="","Esperando el numero de documento...",IF(ISNA(MATCH($C$2,archivo_DATA!$B:$B,0)),"Documento no encontrado. Verifique que este bien escrito.","Estudiante encontrado. Su nota se muestra abajo.")) -> Esperando el numero de documento...
A5: NOTA 1 corresponde a la nota del examen 1, incluyendo las bonificaciones por pasar al tablero y por el ensayo.
A6: DOCUMENTO | B6: APELLIDOS Y NOMBRE | C6: PLAN | D6: CORREO | E6: Bono: pasar al tablero | F6: Bono: ensayo | G6: Puntos | H6: Nota (sin bonos) | I6: NOTA 1 (incluye bonificaciones)
A7: =IF($C$2="","",IF(ISNA(MATCH($C$2,archivo_DATA!$B:$B,0)),"",INDEX(archivo_DATA!B:B,MATCH($C$2,archivo_DATA!$B:$B,0)))) | B7: =IF($C$2="","",IF(ISNA(MATCH($C$2,archivo_DATA!$B:$B,0)),"",INDEX(archivo_DATA!A:A,MATCH($C$2,archivo_DATA!$B:$B,0)))) | C7: =IF($C$2="","",IF(ISNA(MATCH($C$2,archivo_DATA!$B:$B,0)),"",INDEX(archivo_DATA!C:C,MATCH($C$2,archivo_DATA!$B:$B,0)))) | D7: =IF($C$2="","",IF(ISNA(MATCH($C$2,archivo_DATA!$B:$B,0)),"",INDEX(archivo_DATA!E:E,MATCH($C$2,archivo_DATA!$B:$B,0)))) | E7: =IF($C$2="","",IF(ISNA(MATCH($C$2,archivo_DATA!$B:$B,0)),"",INDEX(archivo_DATA!F:F,MATCH($C$2,archivo_DATA!$B:$B,0)))) | F7: =IF($C$2="","",IF(ISNA(MATCH($C$2,archivo_DATA!$B:$B,0)),"",INDEX(archivo_DATA!G:G,MATCH($C$2,archivo_DATA!$B:$B,0)))) | G7: =IF($C$2="","",IF(ISNA(MATCH($C$2,archivo_DATA!$B:$B,0)),"",INDEX(archivo_DATA!H:H,MATCH($C$2,archivo_DATA!$B:$B,0)))) | H7: =IF($C$2="","",IF(ISNA(MATCH($C$2,archivo_DATA!$B:$B,0)),"",INDEX(archivo_DATA!I:I,MATCH($C$2,archivo_DATA!$B:$B,0)))) | I7: =IF($C$2="","",IF(ISNA(MATCH($C$2,archivo_DATA!$B:$B,0)),"",INDEX(archivo_DATA!J:J,MATCH($C$2,archivo_DATA!$B:$B,0))))

Sheet archivo_DATA
A1: APELLIDOS Y NOMBRE | B1: DOCUMENTO | C1: PLAN | D1: OBSERVACIÓN | E1: CORREO | F1: BONO P1 | G1: BONO DEMIS HASSABIS | H1: Puntos | I1: Nota | J1: NOTA 1
A2: ALBA VILLARRAGA, SAMUEL CRISTOBAL | B2: 1076240994 | C2: 2517 - GEOLOGÍA | E2: salbav@unal.edu.co | I2: 0 | J2: =(F2+G2)*0.1+I2 -> 0
A3: ALEJO CRUZ, SIMÓN STEVEN | B3: 1012916858 | C3: 2515 - FARMACIA | E3: salejoc@unal.edu.co | H3: 8 | I3: =(H3+1)/15*5 -> 3 | J3: =(F3+G3)*0.1+I3 -> 3
A4: ALFONSO CAPURRO, MANUEL FEDERICO | B4: 1053327506 | C4: 2515 - FARMACIA | E4: malfonsoc@unal.edu.co | F4: 1 | H4: 11 | I4: =(H4+1)/15*5 -> 4 | J4: =(F4+G4)*0.1+I4 -> 4.1
A5: AMÉZQUITA VELÁSQUEZ, JUAN SEBASTIÁN | B5: 1076907433 | C5: 2513 - BIOLOGÍA | E5: jamezquitav@unal.edu.co | G5: 3 | H5: 2 | I5: =(H5+1)/15*5 -> 1 | J5: =(F5+G5)*0.1+I5 -> 1.3
A6: APRAEZ ENRIQUEZ, JUAN SEBASTIAN | B6: 1123206774 | C6: 2515 - FARMACIA | E6: japraeze@unal.edu.co | F6: 1 | H6: 5 | I6: =(H6+1)/15*5 -> 2 | J6: =(F6+G6)*0.1+I6 -> 2.1
A7: ARDILA CÓRDOBA, MARIANA | B7: 1031810417 | C7: 2515 - FARMACIA | E7: mardilaco@unal.edu.co | F7: 1 | G7: 3 | H7: 3 | I7: =(H7+1)/15*5 -> 1.3333333 | J7: =(F7+G7)*0.1+I7 -> 1.7333333
A8: ARDILA ROBAYO, OSCAR YESID | B8: 1150184601 | C8: 2519 - QUÍMICA | E8: oardila@unal.edu.co | H8: 5 | I8: =(H8+1)/15*5 -> 2 | J8: =(F8+G8)*0.1+I8 -> 2
A9: BAYONA GALLEGO, LIZETH TATIANA | B9: 1028481601 | C9: 2519 - QUÍMICA | E9: lbayonag@unal.edu.co | H9: 3 | I9: =(H9+1)/15*5 -> 1.3333333 | J9: =(F9+G9)*0.1+I9 -> 1.3333333
A10: BERNAL CASTAÑEDA, NICOLAS | B10: 1014978673 | C10: 2517 - GEOLOGÍA | E10: nibernalc@unal.edu.co | F10: 1 | H10: 14 | I10: =(H10+1)/15*5 -> 5 | J10: =(F10+G10)*0.1+I10 -> 5.1
A11: BORDA MALDONADO, CRISTIAN JESHUA | B11: 1093298726 | C11: 2515 - FARMACIA | E11: cbordam@unal.edu.co | F11: 2 | H11: 13 | I11: =(H11+1)/15*5 -> 4.6666667 | J11: =(F11+G11)*0.1+I11 -> 4.8666667
A12: CABRERA CARREÑO, LOREN SOFIA | B12: 1123626503 | C12: 2517 - GEOLOGÍA | E12: locabrerac@unal.edu.co | I12: 0 | J12: =(F12+G12)*0.1+I12 -> 0
A13: CAÑON MELENDRO, JULIAN | B13: 1000132083 | C13: 2519 - QUÍMICA | E13: jcanonme@unal.edu.co | G13: 3 | H13: 10 | I13: =(H13+1)/15*5 -> 3.6666667 | J13: =(F13+G13)*0.1+I13 -> 3.9666667
A14: CONTRERAS CHEMBI, NICOLAS | B14: 1016024758 | C14: 2515 - FARMACIA | E14: ncontrerasc@unal.edu.co | H14: 14 | I14: =(H14+1)/15*5 -> 5 | J14: =(F14+G14)*0.1+I14 -> 5
A15: Cruz Hernández, Divier Alexis | B15: 1101753399 | C15: 2513 - BIOLOGÍA | E15: dicruzh@unal.edu.co | I15: 0 | J15: =(F15+G15)*0.1+I15 -> 0
A16: CUSPOCA CABRA, JULIAN ENRIQUE | B16: 1052402931 | C16: 2519 - QUÍMICA | E16: jecuspocac@unal.edu.co | I16: 0 | J16: =(F16+G16)*0.1+I16 -> 0
A17: ESPINOSA MOSTACILLA, DIEGO ANDRES | B17: 1001068029 | C17: 2515 - FARMACIA | E17: diespinosam@unal.edu.co | F17: 1 | G17: 3 | H17: 12 | I17: =(H17+1)/15*5 -> 4.3333333 | J17: =(F17+G17)*0.1+I17 -> 4.7333333
A18: ESPINOZA MOYA, LUIS FERNANDO | B18: 1032679199 | C18: 2519 - QUÍMICA | E18: lespinozam@unal.edu.co | I18: 0 | J18: =(F18+G18)*0.1+I18 -> 0
A19: FONSECA RESTREPO, JULIANA SOFIA | B19: 1011324993 | C19: 2519 - QUÍMICA | E19: jufonsecar@unal.edu.co | G19: 3 | H19: 6 | I19: =(H19+1)/15*5 -> 2.3333333 | J19: =(F19+G19)*0.1+I19 -> 2.6333333
A20: GARCIA SANABRIA, DANIEL FELIPE | B20: 1074344646 | C20: 2515 - FARMACIA | E20: dgarciasan@unal.edu.co | F20: 1 | G20: 3 | H20: 11 | I20: =(H20+1)/15*5 -> 4 | J20: =(F20+G20)*0.1+I20 -> 4.4
A21: Garzon Vargas, Maximiliano | B21: 1026256714 | C21: 2517 - GEOLOGÍA | E21: mgarzonv@unal.edu.co | H21: 5 | I21: =(H21+1)/15*5 -> 2 | J21: =(F21+G21)*0.1+I21 -> 2
A22: HERNANDEZ PINTO, CARLOS SANTIAGO | B22: 1016953435 | C22: 2519 - QUÍMICA | E22: chernandezpi@unal.edu.co | I22: 0 | J22: =(F22+G22)*0.1+I22 -> 0
A23: HURTADO HURTADO, GLORIA STEPHANIE | B23: 1000714154 | C23: 2513 - BIOLOGÍA | E23: ghurtadoh@unal.edu.co | I23: 0 | J23: =(F23+G23)*0.1+I23 -> 0
A24: JEREZ PUENTES, BRAYAN STEVENT | B24: 1099208375 | C24: 2515 - FARMACIA | E24: bjerez@unal.edu.co | H24: 6 | I24: =(H24+1)/15*5 -> 2.3333333 | J24: =(F24+G24)*0.1+I24 -> 2.3333333
A25: JORDAN BALCAZAR, NICOLAS | B25: 1013114001 | C25: 2513 - BIOLOGÍA | E25: njordan@unal.edu.co | F25: 1 | G25: 3 | H25: 6 | I25: =(H25+1)/15*5 -> 2.3333333 | J25: =(F25+G25)*0.1+I25 -> 2.7333333
A26: MEDINA HERNÁNDEZ, JULIANA | B26: 1070327782 | C26: 2515 - FARMACIA | E26: jmedinahe@unal.edu.co | F26: 1 | G26: 3 | H26: 11 | I26: =(H26+1)/15*5 -> 4 | J26: =(F26+G26)*0.1+I26 -> 4.4
A27: MEDINA NIÑO, NATALIA | B27: 1010005569 | C27: 2519 - QUÍMICA | E27: nmedinan@unal.edu.co | I27: 0 | J27: =(F27+G27)*0.1+I27 -> 0
A28: MONSALVE AGAMEZ, JAIME ANDRES | B28: 1014980652 | C28: 2515 - FARMACIA | E28: jamonsalvea@unal.edu.co | H28: 13 | I28: =(H28+1)/15*5 -> 4.6666667 | J28: =(F28+G28)*0.1+I28 -> 4.6666667
A29: MONTAÑEZ DOMINGUEZ, TOMAS ALBERTO | B29: 1027152242 | C29: 2519 - QUÍMICA | E29: tmontanez@unal.edu.co | H29: 7 | I29: =(H29+1)/15*5 -> 2.6666667 | J29: =(F29+G29)*0.1+I29 -> 2.6666667
A30: MORENO SANCHEZ, SARA SOFIA | B30: 1034780350 | C30: 2513 - BIOLOGÍA | E30: smorenosa@unal.edu.co | G30: 3 | H30: 5 | I30: =(H30+1)/15*5 -> 2 | J30: =(F30+G30)*0.1+I30 -> 2.3
A31: MOSCOSO ENCISO, ALLISON DANIELA | B31: 1024506442 | C31: 2519 - QUÍMICA | E31: amoscosoe@unal.edu.co | I31: 0 | J31: =(F31+G31)*0.1+I31 -> 0
A32: MOSTACILLA HERRERA, MARIE ANNE | B32: 1019986196 | C32: 2519 - QUÍMICA | E32: mmostacilla@unal.edu.co | F32: 2 | G32: 3 | H32: 7 | I32: =(H32+1)/15*5 -> 2.6666667 | J32: =(F32+G32)*0.1+I32 -> 3.1666667
A33: MUÑOZ BÁEZ, EMANUEL | B33: 1019606091 | C33: 2513 - BIOLOGÍA | E33: emmunoz@unal.edu.co | I33: 0 | J33: =(F33+G33)*0.1+I33 -> 0
A34: NARVAEZ LOPEZ, SHAIRA SOFIA | B34: 1052525681 | C34: 2519 - QUÍMICA | E34: snarvaezl@unal.edu.co | F34: 1 | G34: 3 | H34: 11 | I34: =(H34+1)/15*5 -> 4 | J34: =(F34+G34)*0.1+I34 -> 4.4
A35: NUVAN DURAN, JULIAN ANDRES | B35: 1052840598 | C35: 2515 - FARMACIA | E35: jnuvan@unal.edu.co | H35: 7 | I35: =(H35+1)/15*5 -> 2.6666667 | J35: =(F35+G35)*0.1+I35 -> 2.6666667
A36: ORTIZ BUITRAGO, LUIS DAVID | B36: 1001115086 | C36: 2519 - QUÍMICA | E36: luortizb@unal.edu.co | H36: 8 | I36: =(H36+1)/15*5 -> 3 | J36: =(F36+G36)*0.1+I36 -> 3
A37: PEREZ BONILLA, OMAR ENRIQUE | B37: 1000517215 | C37: 2513 - BIOLOGÍA | E37: operezb@unal.edu.co | F37: 1 | H37: 5 | I37: =(H37+1)/15*5 -> 2 | J37: =(F37+G37)*0.1+I37 -> 2.1
A38: PINILLO OROBIO, LESLY LORIETH | B38: 1085547058 | C38: 2513 - BIOLOGÍA | E38: lpinillo@unal.edu.co | I38: 0 | J38: =(F38+G38)*0.1+I38 -> 0
A39: POVEDA CONDE, JULIAN DAVID | B39: 1025322920 | C39: 2515 - FARMACIA | E39: jupoveda@unal.edu.co | F39: 1 | H39: 9 | I39: =(H39+1)/15*5 -> 3.3333333 | J39: =(F39+G39)*0.1+I39 -> 3.4333333
A40: PUERRES ROSERO, EMPERATRIZ | B40: 1089289425 | C40: 2513 - BIOLOGÍA | E40: epuerresr@unal.edu.co | G40: 3 | H40: 3 | I40: =(H40+1)/15*5 -> 1.3333333 | J40: =(F40+G40)*0.1+I40 -> 1.6333333
...
